[2023-01-23T15:42:52.707+0000] {taskinstance.py:1087} INFO - Dependencies all met for <TaskInstance: exercise15.read_users manual__2023-01-23T15:42:50.153087+00:00 [queued]>
[2023-01-23T15:42:52.724+0000] {taskinstance.py:1087} INFO - Dependencies all met for <TaskInstance: exercise15.read_users manual__2023-01-23T15:42:50.153087+00:00 [queued]>
[2023-01-23T15:42:52.725+0000] {taskinstance.py:1283} INFO - 
--------------------------------------------------------------------------------
[2023-01-23T15:42:52.725+0000] {taskinstance.py:1284} INFO - Starting attempt 1 of 1
[2023-01-23T15:42:52.726+0000] {taskinstance.py:1285} INFO - 
--------------------------------------------------------------------------------
[2023-01-23T15:42:52.749+0000] {taskinstance.py:1304} INFO - Executing <Task(_PythonDecoratedOperator): read_users> on 2023-01-23 15:42:50.153087+00:00
[2023-01-23T15:42:52.763+0000] {standard_task_runner.py:55} INFO - Started process 2095 to run task
[2023-01-23T15:42:52.770+0000] {standard_task_runner.py:82} INFO - Running: ['***', 'tasks', 'run', 'exercise15', 'read_users', 'manual__2023-01-23T15:42:50.153087+00:00', '--job-id', '19', '--raw', '--subdir', 'DAGS_FOLDER/exercise15.py', '--cfg-path', '/tmp/tmp8l05ev4x']
[2023-01-23T15:42:52.771+0000] {standard_task_runner.py:83} INFO - Job 19: Subtask read_users
[2023-01-23T15:42:52.870+0000] {task_command.py:389} INFO - Running <TaskInstance: exercise15.read_users manual__2023-01-23T15:42:50.153087+00:00 [running]> on host 05ccfe6a955d
[2023-01-23T15:42:52.994+0000] {taskinstance.py:1513} INFO - Exporting the following env vars:
AIRFLOW_CTX_DAG_OWNER=***
AIRFLOW_CTX_DAG_ID=exercise15
AIRFLOW_CTX_TASK_ID=read_users
AIRFLOW_CTX_EXECUTION_DATE=2023-01-23T15:42:50.153087+00:00
AIRFLOW_CTX_TRY_NUMBER=1
AIRFLOW_CTX_DAG_RUN_ID=manual__2023-01-23T15:42:50.153087+00:00
[2023-01-23T15:42:52.999+0000] {taskinstance.py:1772} ERROR - Task failed with exception
Traceback (most recent call last):
  File "/home/airflow/.local/lib/python3.7/site-packages/airflow/decorators/base.py", line 217, in execute
    return_value = super().execute(context)
  File "/home/airflow/.local/lib/python3.7/site-packages/airflow/operators/python.py", line 175, in execute
    return_value = self.execute_callable()
  File "/home/airflow/.local/lib/python3.7/site-packages/airflow/operators/python.py", line 192, in execute_callable
    return self.python_callable(*self.op_args, **self.op_kwargs)
  File "/opt/airflow/dags/exercise15.py", line 36, in read_users
    with open(path, "r") as f:
FileNotFoundError: [Errno 2] No such file or directory: './dags/data/users.json'
[2023-01-23T15:42:53.014+0000] {taskinstance.py:1327} INFO - Marking task as FAILED. dag_id=exercise15, task_id=read_users, execution_date=20230123T154250, start_date=20230123T154252, end_date=20230123T154253
[2023-01-23T15:42:53.037+0000] {standard_task_runner.py:105} ERROR - Failed to execute job 19 for task read_users ([Errno 2] No such file or directory: './dags/data/users.json'; 2095)
[2023-01-23T15:42:53.068+0000] {local_task_job.py:159} INFO - Task exited with return code 1
[2023-01-23T15:42:53.118+0000] {taskinstance.py:2582} INFO - 0 downstream tasks scheduled from follow-on schedule check
